API Test Report - 2025-04-09 06:41:38
================================================================================


Running tests in: tests/auth
--------------------------------------------------------------------------------
============================= test session starts ==============================
platform linux -- Python 3.12.9, pytest-8.0.2, pluggy-1.5.0 -- /home/ubuntu/miniconda3/envs/keryu/bin/python
cachedir: .pytest_cache
django: version: 5.0.2
rootdir: /home/ubuntu/keryu3
plugins: django-4.8.0
collecting ... collected 11 items

tests/auth/test_authentication.py::AuthenticationTests::test_login_failure FAILED [  9%]
tests/auth/test_authentication.py::AuthenticationTests::test_login_success FAILED [ 18%]
tests/auth/test_authentication.py::AuthenticationTests::test_logout FAILED [ 27%]
tests/auth/test_authentication.py::AuthenticationTests::test_password_change FAILED [ 36%]
tests/auth/test_authentication.py::AuthenticationTests::test_password_reset FAILED [ 45%]
tests/auth/test_authentication.py::APIAuthenticationTests::test_permission_custodian_access FAILED [ 54%]
tests/auth/test_authentication.py::APIAuthenticationTests::test_permission_staff_access FAILED [ 63%]
tests/auth/test_authentication.py::APIAuthenticationTests::test_rate_limiting FAILED [ 72%]
tests/auth/test_authentication.py::APIAuthenticationTests::test_token_authentication FAILED [ 81%]
tests/auth/test_authentication.py::APIAuthenticationTests::test_token_expiration FAILED [ 90%]
tests/auth/test_authentication.py::APIAuthenticationTests::test_unauthorized_access FAILED [100%]

=================================== FAILURES ===================================
____________________ AuthenticationTests.test_login_failure ____________________

self = <django.db.backends.utils.CursorWrapper object at 0x7c27b7435100>
sql = 'INSERT INTO "custodians_custodian" ("user_id", "phone_number", "emergency_phone", "address", "is_verified", "phone_ve... "created_at", "updated_at") VALUES (%s, %s, %s, %s, %s, %s, %s, %s, %s, %s, %s) RETURNING "custodians_custodian"."id"'
params = (12, '+1234567890', None, '', True, False, ...)
ignored_wrapper_args = (False, {'connection': <DatabaseWrapper vendor='sqlite' alias='default'>, 'cursor': <django.db.backends.utils.CursorWrapper object at 0x7c27b7435100>})

    def _execute(self, sql, params, *ignored_wrapper_args):
        # Raise a warning during app initialization (stored_app_configs is only
        # ever set during testing).
        if not apps.ready and not apps.stored_app_configs:
            warnings.warn(self.APPS_NOT_READY_WARNING_MSG, category=RuntimeWarning)
        self.db.validate_no_broken_transaction()
        with self.db.wrap_database_errors:
            if params is None:
                # params default might be backend specific.
                return self.cursor.execute(sql)
            else:
>               return self.cursor.execute(sql, params)

../miniconda3/envs/keryu/lib/python3.12/site-packages/django/db/backends/utils.py:105: 
_ _ _ _ _ _ _ _ _ _ _ _ _ _ _ _ _ _ _ _ _ _ _ _ _ _ _ _ _ _ _ _ _ _ _ _ _ _ _ _ 

self = <django.db.backends.sqlite3.base.SQLiteCursorWrapper object at 0x7c27b7756ba0>
query = 'INSERT INTO "custodians_custodian" ("user_id", "phone_number", "emergency_phone", "address", "is_verified", "phone_ve..._attempts", "created_at", "updated_at") VALUES (?, ?, ?, ?, ?, ?, ?, ?, ?, ?, ?) RETURNING "custodians_custodian"."id"'
params = (12, '+1234567890', None, '', True, False, ...)

    def execute(self, query, params=None):
        if params is None:
            return super().execute(query)
        # Extract names if params is a mapping, i.e. "pyformat" style is used.
        param_names = list(params) if isinstance(params, Mapping) else None
        query = self.convert_query(query, param_names=param_names)
>       return super().execute(query, params)
E       sqlite3.IntegrityError: UNIQUE constraint failed: custodians_custodian.user_id

../miniconda3/envs/keryu/lib/python3.12/site-packages/django/db/backends/sqlite3/base.py:329: IntegrityError

The above exception was the direct cause of the following exception:

self = <test_authentication.AuthenticationTests testMethod=test_login_failure>

    def setUp(self):
        # Create test users
        self.staff_user = User.objects.create_user(
            username='staff',
            password='staffpass123',
            email='staff@example.com',
            is_staff=True
        )
    
        self.custodian_user = User.objects.create_user(
            username='custodian',
            password='custodianpass123',
            email='custodian@example.com'
        )
    
>       self.custodian = Custodian.objects.create(
            user=self.custodian_user,
            phone_number='+1234567890',
            is_verified=True
        )

tests/auth/test_authentication.py:28: 
_ _ _ _ _ _ _ _ _ _ _ _ _ _ _ _ _ _ _ _ _ _ _ _ _ _ _ _ _ _ _ _ _ _ _ _ _ _ _ _ 
../miniconda3/envs/keryu/lib/python3.12/site-packages/django/db/models/manager.py:87: in manager_method
    return getattr(self.get_queryset(), name)(*args, **kwargs)
../miniconda3/envs/keryu/lib/python3.12/site-packages/django/db/models/query.py:679: in create
    obj.save(force_insert=True, using=self.db)
../miniconda3/envs/keryu/lib/python3.12/site-packages/django/db/models/base.py:822: in save
    self.save_base(
../miniconda3/envs/keryu/lib/python3.12/site-packages/django/db/models/base.py:909: in save_base
    updated = self._save_table(
../miniconda3/envs/keryu/lib/python3.12/site-packages/django/db/models/base.py:1067: in _save_table
    results = self._do_insert(
../miniconda3/envs/keryu/lib/python3.12/site-packages/django/db/models/base.py:1108: in _do_insert
    return manager._insert(
../miniconda3/envs/keryu/lib/python3.12/site-packages/django/db/models/manager.py:87: in manager_method
    return getattr(self.get_queryset(), name)(*args, **kwargs)
../miniconda3/envs/keryu/lib/python3.12/site-packages/django/db/models/query.py:1847: in _insert
    return query.get_compiler(using=using).execute_sql(returning_fields)
../miniconda3/envs/keryu/lib/python3.12/site-packages/django/db/models/sql/compiler.py:1823: in execute_sql
    cursor.execute(sql, params)
../miniconda3/envs/keryu/lib/python3.12/site-packages/django/db/backends/utils.py:79: in execute
    return self._execute_with_wrappers(
../miniconda3/envs/keryu/lib/python3.12/site-packages/django/db/backends/utils.py:92: in _execute_with_wrappers
    return executor(sql, params, many, context)
../miniconda3/envs/keryu/lib/python3.12/site-packages/django/db/backends/utils.py:100: in _execute
    with self.db.wrap_database_errors:
../miniconda3/envs/keryu/lib/python3.12/site-packages/django/db/utils.py:91: in __exit__
    raise dj_exc_value.with_traceback(traceback) from exc_value
../miniconda3/envs/keryu/lib/python3.12/site-packages/django/db/backends/utils.py:105: in _execute
    return self.cursor.execute(sql, params)
_ _ _ _ _ _ _ _ _ _ _ _ _ _ _ _ _ _ _ _ _ _ _ _ _ _ _ _ _ _ _ _ _ _ _ _ _ _ _ _ 

self = <django.db.backends.sqlite3.base.SQLiteCursorWrapper object at 0x7c27b7756ba0>
query = 'INSERT INTO "custodians_custodian" ("user_id", "phone_number", "emergency_phone", "address", "is_verified", "phone_ve..._attempts", "created_at", "updated_at") VALUES (?, ?, ?, ?, ?, ?, ?, ?, ?, ?, ?) RETURNING "custodians_custodian"."id"'
params = (12, '+1234567890', None, '', True, False, ...)

    def execute(self, query, params=None):
        if params is None:
            return super().execute(query)
        # Extract names if params is a mapping, i.e. "pyformat" style is used.
        param_names = list(params) if isinstance(params, Mapping) else None
        query = self.convert_query(query, param_names=param_names)
>       return super().execute(query, params)
E       django.db.utils.IntegrityError: UNIQUE constraint failed: custodians_custodian.user_id

../miniconda3/envs/keryu/lib/python3.12/site-packages/django/db/backends/sqlite3/base.py:329: IntegrityError
----------------------------- Captured stderr call -----------------------------
DEBUG 2025-04-09 06:41:40,464 models 5476 136510085551616 Created new custodian for user 11
DEBUG 2025-04-09 06:41:41,022 models 5476 136510085551616 Created new custodian for user 12
------------------------------ Captured log call -------------------------------
DEBUG    custodians.models:models.py:85 Created new custodian for user 11
DEBUG    custodians.models:models.py:85 Created new custodian for user 12
____________________ AuthenticationTests.test_login_success ____________________

self = <django.db.backends.utils.CursorWrapper object at 0x7c27b745b170>
sql = 'INSERT INTO "custodians_custodian" ("user_id", "phone_number", "emergency_phone", "address", "is_verified", "phone_ve... "created_at", "updated_at") VALUES (%s, %s, %s, %s, %s, %s, %s, %s, %s, %s, %s) RETURNING "custodians_custodian"."id"'
params = (12, '+1234567890', None, '', True, False, ...)
ignored_wrapper_args = (False, {'connection': <DatabaseWrapper vendor='sqlite' alias='default'>, 'cursor': <django.db.backends.utils.CursorWrapper object at 0x7c27b745b170>})

    def _execute(self, sql, params, *ignored_wrapper_args):
        # Raise a warning during app initialization (stored_app_configs is only
        # ever set during testing).
        if not apps.ready and not apps.stored_app_configs:
            warnings.warn(self.APPS_NOT_READY_WARNING_MSG, category=RuntimeWarning)
        self.db.validate_no_broken_transaction()
        with self.db.wrap_database_errors:
            if params is None:
                # params default might be backend specific.
                return self.cursor.execute(sql)
            else:
>               return self.cursor.execute(sql, params)

../miniconda3/envs/keryu/lib/python3.12/site-packages/django/db/backends/utils.py:105: 
_ _ _ _ _ _ _ _ _ _ _ _ _ _ _ _ _ _ _ _ _ _ _ _ _ _ _ _ _ _ _ _ _ _ _ _ _ _ _ _ 

self = <django.db.backends.sqlite3.base.SQLiteCursorWrapper object at 0x7c27b7486c30>
query = 'INSERT INTO "custodians_custodian" ("user_id", "phone_number", "emergency_phone", "address", "is_verified", "phone_ve..._attempts", "created_at", "updated_at") VALUES (?, ?, ?, ?, ?, ?, ?, ?, ?, ?, ?) RETURNING "custodians_custodian"."id"'
params = (12, '+1234567890', None, '', True, False, ...)

    def execute(self, query, params=None):
        if params is None:
            return super().execute(query)
        # Extract names if params is a mapping, i.e. "pyformat" style is used.
        param_names = list(params) if isinstance(params, Mapping) else None
        query = self.convert_query(query, param_names=param_names)
>       return super().execute(query, params)
E       sqlite3.IntegrityError: UNIQUE constraint failed: custodians_custodian.user_id

../miniconda3/envs/keryu/lib/python3.12/site-packages/django/db/backends/sqlite3/base.py:329: IntegrityError

The above exception was the direct cause of the following exception:

self = <test_authentication.AuthenticationTests testMethod=test_login_success>

    def setUp(self):
        # Create test users
        self.staff_user = User.objects.create_user(
            username='staff',
            password='staffpass123',
            email='staff@example.com',
            is_staff=True
        )
    
        self.custodian_user = User.objects.create_user(
            username='custodian',
            password='custodianpass123',
            email='custodian@example.com'
        )
    
>       self.custodian = Custodian.objects.create(
            user=self.custodian_user,
            phone_number='+1234567890',
            is_verified=True
        )

tests/auth/test_authentication.py:28: 
_ _ _ _ _ _ _ _ _ _ _ _ _ _ _ _ _ _ _ _ _ _ _ _ _ _ _ _ _ _ _ _ _ _ _ _ _ _ _ _ 
../miniconda3/envs/keryu/lib/python3.12/site-packages/django/db/models/manager.py:87: in manager_method
    return getattr(self.get_queryset(), name)(*args, **kwargs)
../miniconda3/envs/keryu/lib/python3.12/site-packages/django/db/models/query.py:679: in create
    obj.save(force_insert=True, using=self.db)
../miniconda3/envs/keryu/lib/python3.12/site-packages/django/db/models/base.py:822: in save
    self.save_base(
../miniconda3/envs/keryu/lib/python3.12/site-packages/django/db/models/base.py:909: in save_base
    updated = self._save_table(
../miniconda3/envs/keryu/lib/python3.12/site-packages/django/db/models/base.py:1067: in _save_table
    results = self._do_insert(
../miniconda3/envs/keryu/lib/python3.12/site-packages/django/db/models/base.py:1108: in _do_insert
    return manager._insert(
../miniconda3/envs/keryu/lib/python3.12/site-packages/django/db/models/manager.py:87: in manager_method
    return getattr(self.get_queryset(), name)(*args, **kwargs)
../miniconda3/envs/keryu/lib/python3.12/site-packages/django/db/models/query.py:1847: in _insert
    return query.get_compiler(using=using).execute_sql(returning_fields)
../miniconda3/envs/keryu/lib/python3.12/site-packages/django/db/models/sql/compiler.py:1823: in execute_sql
    cursor.execute(sql, params)
../miniconda3/envs/keryu/lib/python3.12/site-packages/django/db/backends/utils.py:79: in execute
    return self._execute_with_wrappers(
../miniconda3/envs/keryu/lib/python3.12/site-packages/django/db/backends/utils.py:92: in _execute_with_wrappers
    return executor(sql, params, many, context)
../miniconda3/envs/keryu/lib/python3.12/site-packages/django/db/backends/utils.py:100: in _execute
    with self.db.wrap_database_errors:
../miniconda3/envs/keryu/lib/python3.12/site-packages/django/db/utils.py:91: in __exit__
    raise dj_exc_value.with_traceback(traceback) from exc_value
../miniconda3/envs/keryu/lib/python3.12/site-packages/django/db/backends/utils.py:105: in _execute
    return self.cursor.execute(sql, params)
_ _ _ _ _ _ _ _ _ _ _ _ _ _ _ _ _ _ _ _ _ _ _ _ _ _ _ _ _ _ _ _ _ _ _ _ _ _ _ _ 

self = <django.db.backends.sqlite3.base.SQLiteCursorWrapper object at 0x7c27b7486c30>
query = 'INSERT INTO "custodians_custodian" ("user_id", "phone_number", "emergency_phone", "address", "is_verified", "phone_ve..._attempts", "created_at", "updated_at") VALUES (?, ?, ?, ?, ?, ?, ?, ?, ?, ?, ?) RETURNING "custodians_custodian"."id"'
params = (12, '+1234567890', None, '', True, False, ...)

    def execute(self, query, params=None):
        if params is None:
            return super().execute(query)
        # Extract names if params is a mapping, i.e. "pyformat" style is used.
        param_names = list(params) if isinstance(params, Mapping) else None
        query = self.convert_query(query, param_names=param_names)
>       return super().execute(query, params)
E       django.db.utils.IntegrityError: UNIQUE constraint failed: custodians_custodian.user_id

../miniconda3/envs/keryu/lib/python3.12/site-packages/django/db/backends/sqlite3/base.py:329: IntegrityError
----------------------------- Captured stderr call -----------------------------
DEBUG 2025-04-09 06:41:41,875 models 5476 136510085551616 Created new custodian for user 11
DEBUG 2025-04-09 06:41:42,432 models 5476 136510085551616 Created new custodian for user 12
------------------------------ Captured log call -------------------------------
DEBUG    custodians.models:models.py:85 Created new custodian for user 11
DEBUG    custodians.models:models.py:85 Created new custodian for user 12
_______________________ AuthenticationTests.test_logout ________________________

self = <django.db.backends.utils.CursorWrapper object at 0x7c27b74a9c40>
sql = 'INSERT INTO "custodians_custodian" ("user_id", "phone_number", "emergency_phone", "address", "is_verified", "phone_ve... "created_at", "updated_at") VALUES (%s, %s, %s, %s, %s, %s, %s, %s, %s, %s, %s) RETURNING "custodians_custodian"."id"'
params = (12, '+1234567890', None, '', True, False, ...)
ignored_wrapper_args = (False, {'connection': <DatabaseWrapper vendor='sqlite' alias='default'>, 'cursor': <django.db.backends.utils.CursorWrapper object at 0x7c27b74a9c40>})

    def _execute(self, sql, params, *ignored_wrapper_args):
        # Raise a warning during app initialization (stored_app_configs is only
        # ever set during testing).
        if not apps.ready and not apps.stored_app_configs:
            warnings.warn(self.APPS_NOT_READY_WARNING_MSG, category=RuntimeWarning)
        self.db.validate_no_broken_transaction()
        with self.db.wrap_database_errors:
            if params is None:
                # params default might be backend specific.
                return self.cursor.execute(sql)
            else:
>               return self.cursor.execute(sql, params)

../miniconda3/envs/keryu/lib/python3.12/site-packages/django/db/backends/utils.py:105: 
_ _ _ _ _ _ _ _ _ _ _ _ _ _ _ _ _ _ _ _ _ _ _ _ _ _ _ _ _ _ _ _ _ _ _ _ _ _ _ _ 

self = <django.db.backends.sqlite3.base.SQLiteCursorWrapper object at 0x7c27b70b4ef0>
query = 'INSERT INTO "custodians_custodian" ("user_id", "phone_number", "emergency_phone", "address", "is_verified", "phone_ve..._attempts", "created_at", "updated_at") VALUES (?, ?, ?, ?, ?, ?, ?, ?, ?, ?, ?) RETURNING "custodians_custodian"."id"'
params = (12, '+1234567890', None, '', True, False, ...)

    def execute(self, query, params=None):
        if params is None:
            return super().execute(query)
        # Extract names if params is a mapping, i.e. "pyformat" style is used.
        param_names = list(params) if isinstance(params, Mapping) else None
        query = self.convert_query(query, param_names=param_names)
>       return super().execute(query, params)
E       sqlite3.IntegrityError: UNIQUE constraint failed: custodians_custodian.user_id

../miniconda3/envs/keryu/lib/python3.12/site-packages/django/db/backends/sqlite3/base.py:329: IntegrityError

The above exception was the direct cause of the following exception:

self = <test_authentication.AuthenticationTests testMethod=test_logout>

    def setUp(self):
        # Create test users
        self.staff_user = User.objects.create_user(
            username='staff',
            password='staffpass123',
            email='staff@example.com',
            is_staff=True
        )
    
        self.custodian_user = User.objects.create_user(
            username='custodian',
            password='custodianpass123',
            email='custodian@example.com'
        )
    
>       self.custodian = Custodian.objects.create(
            user=self.custodian_user,
            phone_number='+1234567890',
            is_verified=True
        )

tests/auth/test_authentication.py:28: 
_ _ _ _ _ _ _ _ _ _ _ _ _ _ _ _ _ _ _ _ _ _ _ _ _ _ _ _ _ _ _ _ _ _ _ _ _ _ _ _ 
../miniconda3/envs/keryu/lib/python3.12/site-packages/django/db/models/manager.py:87: in manager_method
    return getattr(self.get_queryset(), name)(*args, **kwargs)
../miniconda3/envs/keryu/lib/python3.12/site-packages/django/db/models/query.py:679: in create
    obj.save(force_insert=True, using=self.db)
../miniconda3/envs/keryu/lib/python3.12/site-packages/django/db/models/base.py:822: in save
    self.save_base(
../miniconda3/envs/keryu/lib/python3.12/site-packages/django/db/models/base.py:909: in save_base
    updated = self._save_table(
../miniconda3/envs/keryu/lib/python3.12/site-packages/django/db/models/base.py:1067: in _save_table
    results = self._do_insert(
../miniconda3/envs/keryu/lib/python3.12/site-packages/django/db/models/base.py:1108: in _do_insert
    return manager._insert(
../miniconda3/envs/keryu/lib/python3.12/site-packages/django/db/models/manager.py:87: in manager_method
    return getattr(self.get_queryset(), name)(*args, **kwargs)
../miniconda3/envs/keryu/lib/python3.12/site-packages/django/db/models/query.py:1847: in _insert
    return query.get_compiler(using=using).execute_sql(returning_fields)
../miniconda3/envs/keryu/lib/python3.12/site-packages/django/db/models/sql/compiler.py:1823: in execute_sql
    cursor.execute(sql, params)
../miniconda3/envs/keryu/lib/python3.12/site-packages/django/db/backends/utils.py:79: in execute
    return self._execute_with_wrappers(
../miniconda3/envs/keryu/lib/python3.12/site-packages/django/db/backends/utils.py:92: in _execute_with_wrappers
    return executor(sql, params, many, context)
../miniconda3/envs/keryu/lib/python3.12/site-packages/django/db/backends/utils.py:100: in _execute
    with self.db.wrap_database_errors:
../miniconda3/envs/keryu/lib/python3.12/site-packages/django/db/utils.py:91: in __exit__
    raise dj_exc_value.with_traceback(traceback) from exc_value
../miniconda3/envs/keryu/lib/python3.12/site-packages/django/db/backends/utils.py:105: in _execute
    return self.cursor.execute(sql, params)
_ _ _ _ _ _ _ _ _ _ _ _ _ _ _ _ _ _ _ _ _ _ _ _ _ _ _ _ _ _ _ _ _ _ _ _ _ _ _ _ 

self = <django.db.backends.sqlite3.base.SQLiteCursorWrapper object at 0x7c27b70b4ef0>
query = 'INSERT INTO "custodians_custodian" ("user_id", "phone_number", "emergency_phone", "address", "is_verified", "phone_ve..._attempts", "created_at", "updated_at") VALUES (?, ?, ?, ?, ?, ?, ?, ?, ?, ?, ?) RETURNING "custodians_custodian"."id"'
params = (12, '+1234567890', None, '', True, False, ...)

    def execute(self, query, params=None):
        if params is None:
            return super().execute(query)
        # Extract names if params is a mapping, i.e. "pyformat" style is used.
        param_names = list(params) if isinstance(params, Mapping) else None
        query = self.convert_query(query, param_names=param_names)
>       return super().execute(query, params)
E       django.db.utils.IntegrityError: UNIQUE constraint failed: custodians_custodian.user_id

../miniconda3/envs/keryu/lib/python3.12/site-packages/django/db/backends/sqlite3/base.py:329: IntegrityError
----------------------------- Captured stderr call -----------------------------
DEBUG 2025-04-09 06:41:43,166 models 5476 136510085551616 Created new custodian for user 11
DEBUG 2025-04-09 06:41:43,723 models 5476 136510085551616 Created new custodian for user 12
------------------------------ Captured log call -------------------------------
DEBUG    custodians.models:models.py:85 Created new custodian for user 11
DEBUG    custodians.models:models.py:85 Created new custodian for user 12
___________________ AuthenticationTests.test_password_change ___________________

self = <django.db.backends.utils.CursorWrapper object at 0x7c27b74aa7b0>
sql = 'INSERT INTO "custodians_custodian" ("user_id", "phone_number", "emergency_phone", "address", "is_verified", "phone_ve... "created_at", "updated_at") VALUES (%s, %s, %s, %s, %s, %s, %s, %s, %s, %s, %s) RETURNING "custodians_custodian"."id"'
params = (12, '+1234567890', None, '', True, False, ...)
ignored_wrapper_args = (False, {'connection': <DatabaseWrapper vendor='sqlite' alias='default'>, 'cursor': <django.db.backends.utils.CursorWrapper object at 0x7c27b74aa7b0>})

    def _execute(self, sql, params, *ignored_wrapper_args):
        # Raise a warning during app initialization (stored_app_configs is only
        # ever set during testing).
        if not apps.ready and not apps.stored_app_configs:
            warnings.warn(self.APPS_NOT_READY_WARNING_MSG, category=RuntimeWarning)
        self.db.validate_no_broken_transaction()
        with self.db.wrap_database_errors:
            if params is None:
                # params default might be backend specific.
                return self.cursor.execute(sql)
            else:
>               return self.cursor.execute(sql, params)

../miniconda3/envs/keryu/lib/python3.12/site-packages/django/db/backends/utils.py:105: 
_ _ _ _ _ _ _ _ _ _ _ _ _ _ _ _ _ _ _ _ _ _ _ _ _ _ _ _ _ _ _ _ _ _ _ _ _ _ _ _ 

self = <django.db.backends.sqlite3.base.SQLiteCursorWrapper object at 0x7c27b70b6de0>
query = 'INSERT INTO "custodians_custodian" ("user_id", "phone_number", "emergency_phone", "address", "is_verified", "phone_ve..._attempts", "created_at", "updated_at") VALUES (?, ?, ?, ?, ?, ?, ?, ?, ?, ?, ?) RETURNING "custodians_custodian"."id"'
params = (12, '+1234567890', None, '', True, False, ...)

    def execute(self, query, params=None):
        if params is None:
            return super().execute(query)
        # Extract names if params is a mapping, i.e. "pyformat" style is used.
        param_names = list(params) if isinstance(params, Mapping) else None
        query = self.convert_query(query, param_names=param_names)
>       return super().execute(query, params)
E       sqlite3.IntegrityError: UNIQUE constraint failed: custodians_custodian.user_id

../miniconda3/envs/keryu/lib/python3.12/site-packages/django/db/backends/sqlite3/base.py:329: IntegrityError

The above exception was the direct cause of the following exception:

self = <test_authentication.AuthenticationTests testMethod=test_password_change>

    def setUp(self):
        # Create test users
        self.staff_user = User.objects.create_user(
            username='staff',
            password='staffpass123',
            email='staff@example.com',
            is_staff=True
        )
    
        self.custodian_user = User.objects.create_user(
            username='custodian',
            password='custodianpass123',
            email='custodian@example.com'
        )
    
>       self.custodian = Custodian.objects.create(
            user=self.custodian_user,
            phone_number='+1234567890',
            is_verified=True
        )

tests/auth/test_authentication.py:28: 
_ _ _ _ _ _ _ _ _ _ _ _ _ _ _ _ _ _ _ _ _ _ _ _ _ _ _ _ _ _ _ _ _ _ _ _ _ _ _ _ 
../miniconda3/envs/keryu/lib/python3.12/site-packages/django/db/models/manager.py:87: in manager_method
    return getattr(self.get_queryset(), name)(*args, **kwargs)
../miniconda3/envs/keryu/lib/python3.12/site-packages/django/db/models/query.py:679: in create
    obj.save(force_insert=True, using=self.db)
../miniconda3/envs/keryu/lib/python3.12/site-packages/django/db/models/base.py:822: in save
    self.save_base(
../miniconda3/envs/keryu/lib/python3.12/site-packages/django/db/models/base.py:909: in save_base
    updated = self._save_table(
../miniconda3/envs/keryu/lib/python3.12/site-packages/django/db/models/base.py:1067: in _save_table
    results = self._do_insert(
../miniconda3/envs/keryu/lib/python3.12/site-packages/django/db/models/base.py:1108: in _do_insert
    return manager._insert(
../miniconda3/envs/keryu/lib/python3.12/site-packages/django/db/models/manager.py:87: in manager_method
    return getattr(self.get_queryset(), name)(*args, **kwargs)
../miniconda3/envs/keryu/lib/python3.12/site-packages/django/db/models/query.py:1847: in _insert
    return query.get_compiler(using=using).execute_sql(returning_fields)
../miniconda3/envs/keryu/lib/python3.12/site-packages/django/db/models/sql/compiler.py:1823: in execute_sql
    cursor.execute(sql, params)
../miniconda3/envs/keryu/lib/python3.12/site-packages/django/db/backends/utils.py:79: in execute
    return self._execute_with_wrappers(
../miniconda3/envs/keryu/lib/python3.12/site-packages/django/db/backends/utils.py:92: in _execute_with_wrappers
    return executor(sql, params, many, context)
../miniconda3/envs/keryu/lib/python3.12/site-packages/django/db/backends/utils.py:100: in _execute
    with self.db.wrap_database_errors:
../miniconda3/envs/keryu/lib/python3.12/site-packages/django/db/utils.py:91: in __exit__
    raise dj_exc_value.with_traceback(traceback) from exc_value
../miniconda3/envs/keryu/lib/python3.12/site-packages/django/db/backends/utils.py:105: in _execute
    return self.cursor.execute(sql, params)
_ _ _ _ _ _ _ _ _ _ _ _ _ _ _ _ _ _ _ _ _ _ _ _ _ _ _ _ _ _ _ _ _ _ _ _ _ _ _ _ 

self = <django.db.backends.sqlite3.base.SQLiteCursorWrapper object at 0x7c27b70b6de0>
query = 'INSERT INTO "custodians_custodian" ("user_id", "phone_number", "emergency_phone", "address", "is_verified", "phone_ve..._attempts", "created_at", "updated_at") VALUES (?, ?, ?, ?, ?, ?, ?, ?, ?, ?, ?) RETURNING "custodians_custodian"."id"'
params = (12, '+1234567890', None, '', True, False, ...)

    def execute(self, query, params=None):
        if params is None:
            return super().execute(query)
        # Extract names if params is a mapping, i.e. "pyformat" style is used.
        param_names = list(params) if isinstance(params, Mapping) else None
        query = self.convert_query(query, param_names=param_names)
>       return super().execute(query, params)
E       django.db.utils.IntegrityError: UNIQUE constraint failed: custodians_custodian.user_id

../miniconda3/envs/keryu/lib/python3.12/site-packages/django/db/backends/sqlite3/base.py:329: IntegrityError
----------------------------- Captured stderr call -----------------------------
DEBUG 2025-04-09 06:41:44,465 models 5476 136510085551616 Created new custodian for user 11
DEBUG 2025-04-09 06:41:45,023 models 5476 136510085551616 Created new custodian for user 12
------------------------------ Captured log call -------------------------------
DEBUG    custodians.models:models.py:85 Created new custodian for user 11
DEBUG    custodians.models:models.py:85 Created new custodian for user 12
___________________ AuthenticationTests.test_password_reset ____________________

self = <django.db.backends.utils.CursorWrapper object at 0x7c27b74a83b0>
sql = 'INSERT INTO "custodians_custodian" ("user_id", "phone_number", "emergency_phone", "address", "is_verified", "phone_ve... "created_at", "updated_at") VALUES (%s, %s, %s, %s, %s, %s, %s, %s, %s, %s, %s) RETURNING "custodians_custodian"."id"'
params = (12, '+1234567890', None, '', True, False, ...)
ignored_wrapper_args = (False, {'connection': <DatabaseWrapper vendor='sqlite' alias='default'>, 'cursor': <django.db.backends.utils.CursorWrapper object at 0x7c27b74a83b0>})

    def _execute(self, sql, params, *ignored_wrapper_args):
        # Raise a warning during app initialization (stored_app_configs is only
        # ever set during testing).
        if not apps.ready and not apps.stored_app_configs:
            warnings.warn(self.APPS_NOT_READY_WARNING_MSG, category=RuntimeWarning)
        self.db.validate_no_broken_transaction()
        with self.db.wrap_database_errors:
            if params is None:
                # params default might be backend specific.
                return self.cursor.execute(sql)
            else:
>               return self.cursor.execute(sql, params)

../miniconda3/envs/keryu/lib/python3.12/site-packages/django/db/backends/utils.py:105: 
_ _ _ _ _ _ _ _ _ _ _ _ _ _ _ _ _ _ _ _ _ _ _ _ _ _ _ _ _ _ _ _ _ _ _ _ _ _ _ _ 

self = <django.db.backends.sqlite3.base.SQLiteCursorWrapper object at 0x7c27b70b6b10>
query = 'INSERT INTO "custodians_custodian" ("user_id", "phone_number", "emergency_phone", "address", "is_verified", "phone_ve..._attempts", "created_at", "updated_at") VALUES (?, ?, ?, ?, ?, ?, ?, ?, ?, ?, ?) RETURNING "custodians_custodian"."id"'
params = (12, '+1234567890', None, '', True, False, ...)

    def execute(self, query, params=None):
        if params is None:
            return super().execute(query)
        # Extract names if params is a mapping, i.e. "pyformat" style is used.
        param_names = list(params) if isinstance(params, Mapping) else None
        query = self.convert_query(query, param_names=param_names)
>       return super().execute(query, params)
E       sqlite3.IntegrityError: UNIQUE constraint failed: custodians_custodian.user_id

../miniconda3/envs/keryu/lib/python3.12/site-packages/django/db/backends/sqlite3/base.py:329: IntegrityError

The above exception was the direct cause of the following exception:

self = <test_authentication.AuthenticationTests testMethod=test_password_reset>

    def setUp(self):
        # Create test users
        self.staff_user = User.objects.create_user(
            username='staff',
            password='staffpass123',
            email='staff@example.com',
            is_staff=True
        )
    
        self.custodian_user = User.objects.create_user(
            username='custodian',
            password='custodianpass123',
            email='custodian@example.com'
        )
    
>       self.custodian = Custodian.objects.create(
            user=self.custodian_user,
            phone_number='+1234567890',
            is_verified=True
        )

tests/auth/test_authentication.py:28: 
_ _ _ _ _ _ _ _ _ _ _ _ _ _ _ _ _ _ _ _ _ _ _ _ _ _ _ _ _ _ _ _ _ _ _ _ _ _ _ _ 
../miniconda3/envs/keryu/lib/python3.12/site-packages/django/db/models/manager.py:87: in manager_method
    return getattr(self.get_queryset(), name)(*args, **kwargs)
../miniconda3/envs/keryu/lib/python3.12/site-packages/django/db/models/query.py:679: in create
    obj.save(force_insert=True, using=self.db)
../miniconda3/envs/keryu/lib/python3.12/site-packages/django/db/models/base.py:822: in save
    self.save_base(
../miniconda3/envs/keryu/lib/python3.12/site-packages/django/db/models/base.py:909: in save_base
    updated = self._save_table(
../miniconda3/envs/keryu/lib/python3.12/site-packages/django/db/models/base.py:1067: in _save_table
    results = self._do_insert(
../miniconda3/envs/keryu/lib/python3.12/site-packages/django/db/models/base.py:1108: in _do_insert
    return manager._insert(
../miniconda3/envs/keryu/lib/python3.12/site-packages/django/db/models/manager.py:87: in manager_method
    return getattr(self.get_queryset(), name)(*args, **kwargs)
../miniconda3/envs/keryu/lib/python3.12/site-packages/django/db/models/query.py:1847: in _insert
    return query.get_compiler(using=using).execute_sql(returning_fields)
../miniconda3/envs/keryu/lib/python3.12/site-packages/django/db/models/sql/compiler.py:1823: in execute_sql
    cursor.execute(sql, params)
../miniconda3/envs/keryu/lib/python3.12/site-packages/django/db/backends/utils.py:79: in execute
    return self._execute_with_wrappers(
../miniconda3/envs/keryu/lib/python3.12/site-packages/django/db/backends/utils.py:92: in _execute_with_wrappers
    return executor(sql, params, many, context)
../miniconda3/envs/keryu/lib/python3.12/site-packages/django/db/backends/utils.py:100: in _execute
    with self.db.wrap_database_errors:
../miniconda3/envs/keryu/lib/python3.12/site-packages/django/db/utils.py:91: in __exit__
    raise dj_exc_value.with_traceback(traceback) from exc_value
../miniconda3/envs/keryu/lib/python3.12/site-packages/django/db/backends/utils.py:105: in _execute
    return self.cursor.execute(sql, params)
_ _ _ _ _ _ _ _ _ _ _ _ _ _ _ _ _ _ _ _ _ _ _ _ _ _ _ _ _ _ _ _ _ _ _ _ _ _ _ _ 

self = <django.db.backends.sqlite3.base.SQLiteCursorWrapper object at 0x7c27b70b6b10>
query = 'INSERT INTO "custodians_custodian" ("user_id", "phone_number", "emergency_phone", "address", "is_verified", "phone_ve..._attempts", "created_at", "updated_at") VALUES (?, ?, ?, ?, ?, ?, ?, ?, ?, ?, ?) RETURNING "custodians_custodian"."id"'
params = (12, '+1234567890', None, '', True, False, ...)

    def execute(self, query, params=None):
        if params is None:
            return super().execute(query)
        # Extract names if params is a mapping, i.e. "pyformat" style is used.
        param_names = list(params) if isinstance(params, Mapping) else None
        query = self.convert_query(query, param_names=param_names)
>       return super().execute(query, params)
E       django.db.utils.IntegrityError: UNIQUE constraint failed: custodians_custodian.user_id

../miniconda3/envs/keryu/lib/python3.12/site-packages/django/db/backends/sqlite3/base.py:329: IntegrityError
----------------------------- Captured stderr call -----------------------------
DEBUG 2025-04-09 06:41:45,772 models 5476 136510085551616 Created new custodian for user 11
DEBUG 2025-04-09 06:41:46,330 models 5476 136510085551616 Created new custodian for user 12
------------------------------ Captured log call -------------------------------
DEBUG    custodians.models:models.py:85 Created new custodian for user 11
DEBUG    custodians.models:models.py:85 Created new custodian for user 12
___________ APIAuthenticationTests.test_permission_custodian_access ____________

self = <django.db.backends.utils.CursorWrapper object at 0x7c27b79df950>
sql = 'INSERT INTO "custodians_custodian" ("user_id", "phone_number", "emergency_phone", "address", "is_verified", "phone_ve... "created_at", "updated_at") VALUES (%s, %s, %s, %s, %s, %s, %s, %s, %s, %s, %s) RETURNING "custodians_custodian"."id"'
params = (12, '+1234567890', None, '', True, False, ...)
ignored_wrapper_args = (False, {'connection': <DatabaseWrapper vendor='sqlite' alias='default'>, 'cursor': <django.db.backends.utils.CursorWrapper object at 0x7c27b79df950>})

    def _execute(self, sql, params, *ignored_wrapper_args):
        # Raise a warning during app initialization (stored_app_configs is only
        # ever set during testing).
        if not apps.ready and not apps.stored_app_configs:
            warnings.warn(self.APPS_NOT_READY_WARNING_MSG, category=RuntimeWarning)
        self.db.validate_no_broken_transaction()
        with self.db.wrap_database_errors:
            if params is None:
                # params default might be backend specific.
                return self.cursor.execute(sql)
            else:
>               return self.cursor.execute(sql, params)

../miniconda3/envs/keryu/lib/python3.12/site-packages/django/db/backends/utils.py:105: 
_ _ _ _ _ _ _ _ _ _ _ _ _ _ _ _ _ _ _ _ _ _ _ _ _ _ _ _ _ _ _ _ _ _ _ _ _ _ _ _ 

self = <django.db.backends.sqlite3.base.SQLiteCursorWrapper object at 0x7c27b7756a80>
query = 'INSERT INTO "custodians_custodian" ("user_id", "phone_number", "emergency_phone", "address", "is_verified", "phone_ve..._attempts", "created_at", "updated_at") VALUES (?, ?, ?, ?, ?, ?, ?, ?, ?, ?, ?) RETURNING "custodians_custodian"."id"'
params = (12, '+1234567890', None, '', True, False, ...)

    def execute(self, query, params=None):
        if params is None:
            return super().execute(query)
        # Extract names if params is a mapping, i.e. "pyformat" style is used.
        param_names = list(params) if isinstance(params, Mapping) else None
        query = self.convert_query(query, param_names=param_names)
>       return super().execute(query, params)
E       sqlite3.IntegrityError: UNIQUE constraint failed: custodians_custodian.user_id

../miniconda3/envs/keryu/lib/python3.12/site-packages/django/db/backends/sqlite3/base.py:329: IntegrityError

The above exception was the direct cause of the following exception:

self = <test_authentication.APIAuthenticationTests testMethod=test_permission_custodian_access>

    def setUp(self):
        # Create test users
        self.staff_user = User.objects.create_user(
            username='staff',
            password='staffpass123',
            email='staff@example.com',
            is_staff=True
        )
    
        self.custodian_user = User.objects.create_user(
            username='custodian',
            password='custodianpass123',
            email='custodian@example.com'
        )
    
>       self.custodian = Custodian.objects.create(
            user=self.custodian_user,
            phone_number='+1234567890',
            is_verified=True
        )

tests/auth/test_authentication.py:129: 
_ _ _ _ _ _ _ _ _ _ _ _ _ _ _ _ _ _ _ _ _ _ _ _ _ _ _ _ _ _ _ _ _ _ _ _ _ _ _ _ 
../miniconda3/envs/keryu/lib/python3.12/site-packages/django/db/models/manager.py:87: in manager_method
    return getattr(self.get_queryset(), name)(*args, **kwargs)
../miniconda3/envs/keryu/lib/python3.12/site-packages/django/db/models/query.py:679: in create
    obj.save(force_insert=True, using=self.db)
../miniconda3/envs/keryu/lib/python3.12/site-packages/django/db/models/base.py:822: in save
    self.save_base(
../miniconda3/envs/keryu/lib/python3.12/site-packages/django/db/models/base.py:909: in save_base
    updated = self._save_table(
../miniconda3/envs/keryu/lib/python3.12/site-packages/django/db/models/base.py:1067: in _save_table
    results = self._do_insert(
../miniconda3/envs/keryu/lib/python3.12/site-packages/django/db/models/base.py:1108: in _do_insert
    return manager._insert(
../miniconda3/envs/keryu/lib/python3.12/site-packages/django/db/models/manager.py:87: in manager_method
    return getattr(self.get_queryset(), name)(*args, **kwargs)
../miniconda3/envs/keryu/lib/python3.12/site-packages/django/db/models/query.py:1847: in _insert
    return query.get_compiler(using=using).execute_sql(returning_fields)
../miniconda3/envs/keryu/lib/python3.12/site-packages/django/db/models/sql/compiler.py:1823: in execute_sql
    cursor.execute(sql, params)
../miniconda3/envs/keryu/lib/python3.12/site-packages/django/db/backends/utils.py:79: in execute
    return self._execute_with_wrappers(
../miniconda3/envs/keryu/lib/python3.12/site-packages/django/db/backends/utils.py:92: in _execute_with_wrappers
    return executor(sql, params, many, context)
../miniconda3/envs/keryu/lib/python3.12/site-packages/django/db/backends/utils.py:100: in _execute
    with self.db.wrap_database_errors:
../miniconda3/envs/keryu/lib/python3.12/site-packages/django/db/utils.py:91: in __exit__
    raise dj_exc_value.with_traceback(traceback) from exc_value
../miniconda3/envs/keryu/lib/python3.12/site-packages/django/db/backends/utils.py:105: in _execute
    return self.cursor.execute(sql, params)
_ _ _ _ _ _ _ _ _ _ _ _ _ _ _ _ _ _ _ _ _ _ _ _ _ _ _ _ _ _ _ _ _ _ _ _ _ _ _ _ 

self = <django.db.backends.sqlite3.base.SQLiteCursorWrapper object at 0x7c27b7756a80>
query = 'INSERT INTO "custodians_custodian" ("user_id", "phone_number", "emergency_phone", "address", "is_verified", "phone_ve..._attempts", "created_at", "updated_at") VALUES (?, ?, ?, ?, ?, ?, ?, ?, ?, ?, ?) RETURNING "custodians_custodian"."id"'
params = (12, '+1234567890', None, '', True, False, ...)

    def execute(self, query, params=None):
        if params is None:
            return super().execute(query)
        # Extract names if params is a mapping, i.e. "pyformat" style is used.
        param_names = list(params) if isinstance(params, Mapping) else None
        query = self.convert_query(query, param_names=param_names)
>       return super().execute(query, params)
E       django.db.utils.IntegrityError: UNIQUE constraint failed: custodians_custodian.user_id

../miniconda3/envs/keryu/lib/python3.12/site-packages/django/db/backends/sqlite3/base.py:329: IntegrityError
----------------------------- Captured stderr call -----------------------------
DEBUG 2025-04-09 06:41:47,099 models 5476 136510085551616 Created new custodian for user 11
DEBUG 2025-04-09 06:41:47,657 models 5476 136510085551616 Created new custodian for user 12
------------------------------ Captured log call -------------------------------
DEBUG    custodians.models:models.py:85 Created new custodian for user 11
DEBUG    custodians.models:models.py:85 Created new custodian for user 12
_____________ APIAuthenticationTests.test_permission_staff_access ______________

self = <django.db.backends.utils.CursorWrapper object at 0x7c27b74aa600>
sql = 'INSERT INTO "custodians_custodian" ("user_id", "phone_number", "emergency_phone", "address", "is_verified", "phone_ve... "created_at", "updated_at") VALUES (%s, %s, %s, %s, %s, %s, %s, %s, %s, %s, %s) RETURNING "custodians_custodian"."id"'
params = (12, '+1234567890', None, '', True, False, ...)
ignored_wrapper_args = (False, {'connection': <DatabaseWrapper vendor='sqlite' alias='default'>, 'cursor': <django.db.backends.utils.CursorWrapper object at 0x7c27b74aa600>})

    def _execute(self, sql, params, *ignored_wrapper_args):
        # Raise a warning during app initialization (stored_app_configs is only
        # ever set during testing).
        if not apps.ready and not apps.stored_app_configs:
            warnings.warn(self.APPS_NOT_READY_WARNING_MSG, category=RuntimeWarning)
        self.db.validate_no_broken_transaction()
        with self.db.wrap_database_errors:
            if params is None:
                # params default might be backend specific.
                return self.cursor.execute(sql)
            else:
>               return self.cursor.execute(sql, params)

../miniconda3/envs/keryu/lib/python3.12/site-packages/django/db/backends/utils.py:105: 
_ _ _ _ _ _ _ _ _ _ _ _ _ _ _ _ _ _ _ _ _ _ _ _ _ _ _ _ _ _ _ _ _ _ _ _ _ _ _ _ 

self = <django.db.backends.sqlite3.base.SQLiteCursorWrapper object at 0x7c27b7756ba0>
query = 'INSERT INTO "custodians_custodian" ("user_id", "phone_number", "emergency_phone", "address", "is_verified", "phone_ve..._attempts", "created_at", "updated_at") VALUES (?, ?, ?, ?, ?, ?, ?, ?, ?, ?, ?) RETURNING "custodians_custodian"."id"'
params = (12, '+1234567890', None, '', True, False, ...)

    def execute(self, query, params=None):
        if params is None:
            return super().execute(query)
        # Extract names if params is a mapping, i.e. "pyformat" style is used.
        param_names = list(params) if isinstance(params, Mapping) else None
        query = self.convert_query(query, param_names=param_names)
>       return super().execute(query, params)
E       sqlite3.IntegrityError: UNIQUE constraint failed: custodians_custodian.user_id

../miniconda3/envs/keryu/lib/python3.12/site-packages/django/db/backends/sqlite3/base.py:329: IntegrityError

The above exception was the direct cause of the following exception:

self = <test_authentication.APIAuthenticationTests testMethod=test_permission_staff_access>

    def setUp(self):
        # Create test users
        self.staff_user = User.objects.create_user(
            username='staff',
            password='staffpass123',
            email='staff@example.com',
            is_staff=True
        )
    
        self.custodian_user = User.objects.create_user(
            username='custodian',
            password='custodianpass123',
            email='custodian@example.com'
        )
    
>       self.custodian = Custodian.objects.create(
            user=self.custodian_user,
            phone_number='+1234567890',
            is_verified=True
        )

tests/auth/test_authentication.py:129: 
_ _ _ _ _ _ _ _ _ _ _ _ _ _ _ _ _ _ _ _ _ _ _ _ _ _ _ _ _ _ _ _ _ _ _ _ _ _ _ _ 
../miniconda3/envs/keryu/lib/python3.12/site-packages/django/db/models/manager.py:87: in manager_method
    return getattr(self.get_queryset(), name)(*args, **kwargs)
../miniconda3/envs/keryu/lib/python3.12/site-packages/django/db/models/query.py:679: in create
    obj.save(force_insert=True, using=self.db)
../miniconda3/envs/keryu/lib/python3.12/site-packages/django/db/models/base.py:822: in save
    self.save_base(
../miniconda3/envs/keryu/lib/python3.12/site-packages/django/db/models/base.py:909: in save_base
    updated = self._save_table(
../miniconda3/envs/keryu/lib/python3.12/site-packages/django/db/models/base.py:1067: in _save_table
    results = self._do_insert(
../miniconda3/envs/keryu/lib/python3.12/site-packages/django/db/models/base.py:1108: in _do_insert
    return manager._insert(
../miniconda3/envs/keryu/lib/python3.12/site-packages/django/db/models/manager.py:87: in manager_method
    return getattr(self.get_queryset(), name)(*args, **kwargs)
../miniconda3/envs/keryu/lib/python3.12/site-packages/django/db/models/query.py:1847: in _insert
    return query.get_compiler(using=using).execute_sql(returning_fields)
../miniconda3/envs/keryu/lib/python3.12/site-packages/django/db/models/sql/compiler.py:1823: in execute_sql
    cursor.execute(sql, params)
../miniconda3/envs/keryu/lib/python3.12/site-packages/django/db/backends/utils.py:79: in execute
    return self._execute_with_wrappers(
../miniconda3/envs/keryu/lib/python3.12/site-packages/django/db/backends/utils.py:92: in _execute_with_wrappers
    return executor(sql, params, many, context)
../miniconda3/envs/keryu/lib/python3.12/site-packages/django/db/backends/utils.py:100: in _execute
    with self.db.wrap_database_errors:
../miniconda3/envs/keryu/lib/python3.12/site-packages/django/db/utils.py:91: in __exit__
    raise dj_exc_value.with_traceback(traceback) from exc_value
../miniconda3/envs/keryu/lib/python3.12/site-packages/django/db/backends/utils.py:105: in _execute
    return self.cursor.execute(sql, params)
_ _ _ _ _ _ _ _ _ _ _ _ _ _ _ _ _ _ _ _ _ _ _ _ _ _ _ _ _ _ _ _ _ _ _ _ _ _ _ _ 

self = <django.db.backends.sqlite3.base.SQLiteCursorWrapper object at 0x7c27b7756ba0>
query = 'INSERT INTO "custodians_custodian" ("user_id", "phone_number", "emergency_phone", "address", "is_verified", "phone_ve..._attempts", "created_at", "updated_at") VALUES (?, ?, ?, ?, ?, ?, ?, ?, ?, ?, ?) RETURNING "custodians_custodian"."id"'
params = (12, '+1234567890', None, '', True, False, ...)

    def execute(self, query, params=None):
        if params is None:
            return super().execute(query)
        # Extract names if params is a mapping, i.e. "pyformat" style is used.
        param_names = list(params) if isinstance(params, Mapping) else None
        query = self.convert_query(query, param_names=param_names)
>       return super().execute(query, params)
E       django.db.utils.IntegrityError: UNIQUE constraint failed: custodians_custodian.user_id

../miniconda3/envs/keryu/lib/python3.12/site-packages/django/db/backends/sqlite3/base.py:329: IntegrityError
----------------------------- Captured stderr call -----------------------------
DEBUG 2025-04-09 06:41:48,403 models 5476 136510085551616 Created new custodian for user 11
DEBUG 2025-04-09 06:41:48,961 models 5476 136510085551616 Created new custodian for user 12
------------------------------ Captured log call -------------------------------
DEBUG    custodians.models:models.py:85 Created new custodian for user 11
DEBUG    custodians.models:models.py:85 Created new custodian for user 12
__________________ APIAuthenticationTests.test_rate_limiting ___________________

self = <django.db.backends.utils.CursorWrapper object at 0x7c27b72f4290>
sql = 'INSERT INTO "custodians_custodian" ("user_id", "phone_number", "emergency_phone", "address", "is_verified", "phone_ve... "created_at", "updated_at") VALUES (%s, %s, %s, %s, %s, %s, %s, %s, %s, %s, %s) RETURNING "custodians_custodian"."id"'
params = (12, '+1234567890', None, '', True, False, ...)
ignored_wrapper_args = (False, {'connection': <DatabaseWrapper vendor='sqlite' alias='default'>, 'cursor': <django.db.backends.utils.CursorWrapper object at 0x7c27b72f4290>})

    def _execute(self, sql, params, *ignored_wrapper_args):
        # Raise a warning during app initialization (stored_app_configs is only
        # ever set during testing).
        if not apps.ready and not apps.stored_app_configs:
            warnings.warn(self.APPS_NOT_READY_WARNING_MSG, category=RuntimeWarning)
        self.db.validate_no_broken_transaction()
        with self.db.wrap_database_errors:
            if params is None:
                # params default might be backend specific.
                return self.cursor.execute(sql)
            else:
>               return self.cursor.execute(sql, params)

../miniconda3/envs/keryu/lib/python3.12/site-packages/django/db/backends/utils.py:105: 
_ _ _ _ _ _ _ _ _ _ _ _ _ _ _ _ _ _ _ _ _ _ _ _ _ _ _ _ _ _ _ _ _ _ _ _ _ _ _ _ 

self = <django.db.backends.sqlite3.base.SQLiteCursorWrapper object at 0x7c27b70b5370>
query = 'INSERT INTO "custodians_custodian" ("user_id", "phone_number", "emergency_phone", "address", "is_verified", "phone_ve..._attempts", "created_at", "updated_at") VALUES (?, ?, ?, ?, ?, ?, ?, ?, ?, ?, ?) RETURNING "custodians_custodian"."id"'
params = (12, '+1234567890', None, '', True, False, ...)

    def execute(self, query, params=None):
        if params is None:
            return super().execute(query)
        # Extract names if params is a mapping, i.e. "pyformat" style is used.
        param_names = list(params) if isinstance(params, Mapping) else None
        query = self.convert_query(query, param_names=param_names)
>       return super().execute(query, params)
E       sqlite3.IntegrityError: UNIQUE constraint failed: custodians_custodian.user_id

../miniconda3/envs/keryu/lib/python3.12/site-packages/django/db/backends/sqlite3/base.py:329: IntegrityError

The above exception was the direct cause of the following exception:

self = <test_authentication.APIAuthenticationTests testMethod=test_rate_limiting>

    def setUp(self):
        # Create test users
        self.staff_user = User.objects.create_user(
            username='staff',
            password='staffpass123',
            email='staff@example.com',
            is_staff=True
        )
    
        self.custodian_user = User.objects.create_user(
            username='custodian',
            password='custodianpass123',
            email='custodian@example.com'
        )
    
>       self.custodian = Custodian.objects.create(
            user=self.custodian_user,
            phone_number='+1234567890',
            is_verified=True
        )

tests/auth/test_authentication.py:129: 
_ _ _ _ _ _ _ _ _ _ _ _ _ _ _ _ _ _ _ _ _ _ _ _ _ _ _ _ _ _ _ _ _ _ _ _ _ _ _ _ 
../miniconda3/envs/keryu/lib/python3.12/site-packages/django/db/models/manager.py:87: in manager_method
    return getattr(self.get_queryset(), name)(*args, **kwargs)
../miniconda3/envs/keryu/lib/python3.12/site-packages/django/db/models/query.py:679: in create
    obj.save(force_insert=True, using=self.db)
../miniconda3/envs/keryu/lib/python3.12/site-packages/django/db/models/base.py:822: in save
    self.save_base(
../miniconda3/envs/keryu/lib/python3.12/site-packages/django/db/models/base.py:909: in save_base
    updated = self._save_table(
../miniconda3/envs/keryu/lib/python3.12/site-packages/django/db/models/base.py:1067: in _save_table
    results = self._do_insert(
../miniconda3/envs/keryu/lib/python3.12/site-packages/django/db/models/base.py:1108: in _do_insert
    return manager._insert(
../miniconda3/envs/keryu/lib/python3.12/site-packages/django/db/models/manager.py:87: in manager_method
    return getattr(self.get_queryset(), name)(*args, **kwargs)
../miniconda3/envs/keryu/lib/python3.12/site-packages/django/db/models/query.py:1847: in _insert
    return query.get_compiler(using=using).execute_sql(returning_fields)
../miniconda3/envs/keryu/lib/python3.12/site-packages/django/db/models/sql/compiler.py:1823: in execute_sql
    cursor.execute(sql, params)
../miniconda3/envs/keryu/lib/python3.12/site-packages/django/db/backends/utils.py:79: in execute
    return self._execute_with_wrappers(
../miniconda3/envs/keryu/lib/python3.12/site-packages/django/db/backends/utils.py:92: in _execute_with_wrappers
    return executor(sql, params, many, context)
../miniconda3/envs/keryu/lib/python3.12/site-packages/django/db/backends/utils.py:100: in _execute
    with self.db.wrap_database_errors:
../miniconda3/envs/keryu/lib/python3.12/site-packages/django/db/utils.py:91: in __exit__
    raise dj_exc_value.with_traceback(traceback) from exc_value
../miniconda3/envs/keryu/lib/python3.12/site-packages/django/db/backends/utils.py:105: in _execute
    return self.cursor.execute(sql, params)
_ _ _ _ _ _ _ _ _ _ _ _ _ _ _ _ _ _ _ _ _ _ _ _ _ _ _ _ _ _ _ _ _ _ _ _ _ _ _ _ 

self = <django.db.backends.sqlite3.base.SQLiteCursorWrapper object at 0x7c27b70b5370>
query = 'INSERT INTO "custodians_custodian" ("user_id", "phone_number", "emergency_phone", "address", "is_verified", "phone_ve..._attempts", "created_at", "updated_at") VALUES (?, ?, ?, ?, ?, ?, ?, ?, ?, ?, ?) RETURNING "custodians_custodian"."id"'
params = (12, '+1234567890', None, '', True, False, ...)

    def execute(self, query, params=None):
        if params is None:
            return super().execute(query)
        # Extract names if params is a mapping, i.e. "pyformat" style is used.
        param_names = list(params) if isinstance(params, Mapping) else None
        query = self.convert_query(query, param_names=param_names)
>       return super().execute(query, params)
E       django.db.utils.IntegrityError: UNIQUE constraint failed: custodians_custodian.user_id

../miniconda3/envs/keryu/lib/python3.12/site-packages/django/db/backends/sqlite3/base.py:329: IntegrityError
----------------------------- Captured stderr call -----------------------------
DEBUG 2025-04-09 06:41:49,700 models 5476 136510085551616 Created new custodian for user 11
DEBUG 2025-04-09 06:41:50,257 models 5476 136510085551616 Created new custodian for user 12
------------------------------ Captured log call -------------------------------
DEBUG    custodians.models:models.py:85 Created new custodian for user 11
DEBUG    custodians.models:models.py:85 Created new custodian for user 12
_______________ APIAuthenticationTests.test_token_authentication _______________

self = <django.db.backends.utils.CursorWrapper object at 0x7c27b72f4680>
sql = 'INSERT INTO "custodians_custodian" ("user_id", "phone_number", "emergency_phone", "address", "is_verified", "phone_ve... "created_at", "updated_at") VALUES (%s, %s, %s, %s, %s, %s, %s, %s, %s, %s, %s) RETURNING "custodians_custodian"."id"'
params = (12, '+1234567890', None, '', True, False, ...)
ignored_wrapper_args = (False, {'connection': <DatabaseWrapper vendor='sqlite' alias='default'>, 'cursor': <django.db.backends.utils.CursorWrapper object at 0x7c27b72f4680>})

    def _execute(self, sql, params, *ignored_wrapper_args):
        # Raise a warning during app initialization (stored_app_configs is only
        # ever set during testing).
        if not apps.ready and not apps.stored_app_configs:
            warnings.warn(self.APPS_NOT_READY_WARNING_MSG, category=RuntimeWarning)
        self.db.validate_no_broken_transaction()
        with self.db.wrap_database_errors:
            if params is None:
                # params default might be backend specific.
                return self.cursor.execute(sql)
            else:
>               return self.cursor.execute(sql, params)

../miniconda3/envs/keryu/lib/python3.12/site-packages/django/db/backends/utils.py:105: 
_ _ _ _ _ _ _ _ _ _ _ _ _ _ _ _ _ _ _ _ _ _ _ _ _ _ _ _ _ _ _ _ _ _ _ _ _ _ _ _ 

self = <django.db.backends.sqlite3.base.SQLiteCursorWrapper object at 0x7c27b70b68d0>
query = 'INSERT INTO "custodians_custodian" ("user_id", "phone_number", "emergency_phone", "address", "is_verified", "phone_ve..._attempts", "created_at", "updated_at") VALUES (?, ?, ?, ?, ?, ?, ?, ?, ?, ?, ?) RETURNING "custodians_custodian"."id"'
params = (12, '+1234567890', None, '', True, False, ...)

    def execute(self, query, params=None):
        if params is None:
            return super().execute(query)
        # Extract names if params is a mapping, i.e. "pyformat" style is used.
        param_names = list(params) if isinstance(params, Mapping) else None
        query = self.convert_query(query, param_names=param_names)
>       return super().execute(query, params)
E       sqlite3.IntegrityError: UNIQUE constraint failed: custodians_custodian.user_id

../miniconda3/envs/keryu/lib/python3.12/site-packages/django/db/backends/sqlite3/base.py:329: IntegrityError

The above exception was the direct cause of the following exception:

self = <test_authentication.APIAuthenticationTests testMethod=test_token_authentication>

    def setUp(self):
        # Create test users
        self.staff_user = User.objects.create_user(
            username='staff',
            password='staffpass123',
            email='staff@example.com',
            is_staff=True
        )
    
        self.custodian_user = User.objects.create_user(
            username='custodian',
            password='custodianpass123',
            email='custodian@example.com'
        )
    
>       self.custodian = Custodian.objects.create(
            user=self.custodian_user,
            phone_number='+1234567890',
            is_verified=True
        )

tests/auth/test_authentication.py:129: 
_ _ _ _ _ _ _ _ _ _ _ _ _ _ _ _ _ _ _ _ _ _ _ _ _ _ _ _ _ _ _ _ _ _ _ _ _ _ _ _ 
../miniconda3/envs/keryu/lib/python3.12/site-packages/django/db/models/manager.py:87: in manager_method
    return getattr(self.get_queryset(), name)(*args, **kwargs)
../miniconda3/envs/keryu/lib/python3.12/site-packages/django/db/models/query.py:679: in create
    obj.save(force_insert=True, using=self.db)
../miniconda3/envs/keryu/lib/python3.12/site-packages/django/db/models/base.py:822: in save
    self.save_base(
../miniconda3/envs/keryu/lib/python3.12/site-packages/django/db/models/base.py:909: in save_base
    updated = self._save_table(
../miniconda3/envs/keryu/lib/python3.12/site-packages/django/db/models/base.py:1067: in _save_table
    results = self._do_insert(
../miniconda3/envs/keryu/lib/python3.12/site-packages/django/db/models/base.py:1108: in _do_insert
    return manager._insert(
../miniconda3/envs/keryu/lib/python3.12/site-packages/django/db/models/manager.py:87: in manager_method
    return getattr(self.get_queryset(), name)(*args, **kwargs)
../miniconda3/envs/keryu/lib/python3.12/site-packages/django/db/models/query.py:1847: in _insert
    return query.get_compiler(using=using).execute_sql(returning_fields)
../miniconda3/envs/keryu/lib/python3.12/site-packages/django/db/models/sql/compiler.py:1823: in execute_sql
    cursor.execute(sql, params)
../miniconda3/envs/keryu/lib/python3.12/site-packages/django/db/backends/utils.py:79: in execute
    return self._execute_with_wrappers(
../miniconda3/envs/keryu/lib/python3.12/site-packages/django/db/backends/utils.py:92: in _execute_with_wrappers
    return executor(sql, params, many, context)
../miniconda3/envs/keryu/lib/python3.12/site-packages/django/db/backends/utils.py:100: in _execute
    with self.db.wrap_database_errors:
../miniconda3/envs/keryu/lib/python3.12/site-packages/django/db/utils.py:91: in __exit__
    raise dj_exc_value.with_traceback(traceback) from exc_value
../miniconda3/envs/keryu/lib/python3.12/site-packages/django/db/backends/utils.py:105: in _execute
    return self.cursor.execute(sql, params)
_ _ _ _ _ _ _ _ _ _ _ _ _ _ _ _ _ _ _ _ _ _ _ _ _ _ _ _ _ _ _ _ _ _ _ _ _ _ _ _ 

self = <django.db.backends.sqlite3.base.SQLiteCursorWrapper object at 0x7c27b70b68d0>
query = 'INSERT INTO "custodians_custodian" ("user_id", "phone_number", "emergency_phone", "address", "is_verified", "phone_ve..._attempts", "created_at", "updated_at") VALUES (?, ?, ?, ?, ?, ?, ?, ?, ?, ?, ?) RETURNING "custodians_custodian"."id"'
params = (12, '+1234567890', None, '', True, False, ...)

    def execute(self, query, params=None):
        if params is None:
            return super().execute(query)
        # Extract names if params is a mapping, i.e. "pyformat" style is used.
        param_names = list(params) if isinstance(params, Mapping) else None
        query = self.convert_query(query, param_names=param_names)
>       return super().execute(query, params)
E       django.db.utils.IntegrityError: UNIQUE constraint failed: custodians_custodian.user_id

../miniconda3/envs/keryu/lib/python3.12/site-packages/django/db/backends/sqlite3/base.py:329: IntegrityError
----------------------------- Captured stderr call -----------------------------
DEBUG 2025-04-09 06:41:50,999 models 5476 136510085551616 Created new custodian for user 11
DEBUG 2025-04-09 06:41:51,555 models 5476 136510085551616 Created new custodian for user 12
------------------------------ Captured log call -------------------------------
DEBUG    custodians.models:models.py:85 Created new custodian for user 11
DEBUG    custodians.models:models.py:85 Created new custodian for user 12
_________________ APIAuthenticationTests.test_token_expiration _________________

self = <django.db.backends.utils.CursorWrapper object at 0x7c27b72f6f30>
sql = 'INSERT INTO "custodians_custodian" ("user_id", "phone_number", "emergency_phone", "address", "is_verified", "phone_ve... "created_at", "updated_at") VALUES (%s, %s, %s, %s, %s, %s, %s, %s, %s, %s, %s) RETURNING "custodians_custodian"."id"'
params = (12, '+1234567890', None, '', True, False, ...)
ignored_wrapper_args = (False, {'connection': <DatabaseWrapper vendor='sqlite' alias='default'>, 'cursor': <django.db.backends.utils.CursorWrapper object at 0x7c27b72f6f30>})

    def _execute(self, sql, params, *ignored_wrapper_args):
        # Raise a warning during app initialization (stored_app_configs is only
        # ever set during testing).
        if not apps.ready and not apps.stored_app_configs:
            warnings.warn(self.APPS_NOT_READY_WARNING_MSG, category=RuntimeWarning)
        self.db.validate_no_broken_transaction()
        with self.db.wrap_database_errors:
            if params is None:
                # params default might be backend specific.
                return self.cursor.execute(sql)
            else:
>               return self.cursor.execute(sql, params)

../miniconda3/envs/keryu/lib/python3.12/site-packages/django/db/backends/utils.py:105: 
_ _ _ _ _ _ _ _ _ _ _ _ _ _ _ _ _ _ _ _ _ _ _ _ _ _ _ _ _ _ _ _ _ _ _ _ _ _ _ _ 

self = <django.db.backends.sqlite3.base.SQLiteCursorWrapper object at 0x7c27b70b5130>
query = 'INSERT INTO "custodians_custodian" ("user_id", "phone_number", "emergency_phone", "address", "is_verified", "phone_ve..._attempts", "created_at", "updated_at") VALUES (?, ?, ?, ?, ?, ?, ?, ?, ?, ?, ?) RETURNING "custodians_custodian"."id"'
params = (12, '+1234567890', None, '', True, False, ...)

    def execute(self, query, params=None):
        if params is None:
            return super().execute(query)
        # Extract names if params is a mapping, i.e. "pyformat" style is used.
        param_names = list(params) if isinstance(params, Mapping) else None
        query = self.convert_query(query, param_names=param_names)
>       return super().execute(query, params)
E       sqlite3.IntegrityError: UNIQUE constraint failed: custodians_custodian.user_id

../miniconda3/envs/keryu/lib/python3.12/site-packages/django/db/backends/sqlite3/base.py:329: IntegrityError

The above exception was the direct cause of the following exception:

self = <test_authentication.APIAuthenticationTests testMethod=test_token_expiration>

    def setUp(self):
        # Create test users
        self.staff_user = User.objects.create_user(
            username='staff',
            password='staffpass123',
            email='staff@example.com',
            is_staff=True
        )
    
        self.custodian_user = User.objects.create_user(
            username='custodian',
            password='custodianpass123',
            email='custodian@example.com'
        )
    
>       self.custodian = Custodian.objects.create(
            user=self.custodian_user,
            phone_number='+1234567890',
            is_verified=True
        )

tests/auth/test_authentication.py:129: 
_ _ _ _ _ _ _ _ _ _ _ _ _ _ _ _ _ _ _ _ _ _ _ _ _ _ _ _ _ _ _ _ _ _ _ _ _ _ _ _ 
../miniconda3/envs/keryu/lib/python3.12/site-packages/django/db/models/manager.py:87: in manager_method
    return getattr(self.get_queryset(), name)(*args, **kwargs)
../miniconda3/envs/keryu/lib/python3.12/site-packages/django/db/models/query.py:679: in create
    obj.save(force_insert=True, using=self.db)
../miniconda3/envs/keryu/lib/python3.12/site-packages/django/db/models/base.py:822: in save
    self.save_base(
../miniconda3/envs/keryu/lib/python3.12/site-packages/django/db/models/base.py:909: in save_base
    updated = self._save_table(
../miniconda3/envs/keryu/lib/python3.12/site-packages/django/db/models/base.py:1067: in _save_table
    results = self._do_insert(
../miniconda3/envs/keryu/lib/python3.12/site-packages/django/db/models/base.py:1108: in _do_insert
    return manager._insert(
../miniconda3/envs/keryu/lib/python3.12/site-packages/django/db/models/manager.py:87: in manager_method
    return getattr(self.get_queryset(), name)(*args, **kwargs)
../miniconda3/envs/keryu/lib/python3.12/site-packages/django/db/models/query.py:1847: in _insert
    return query.get_compiler(using=using).execute_sql(returning_fields)
../miniconda3/envs/keryu/lib/python3.12/site-packages/django/db/models/sql/compiler.py:1823: in execute_sql
    cursor.execute(sql, params)
../miniconda3/envs/keryu/lib/python3.12/site-packages/django/db/backends/utils.py:79: in execute
    return self._execute_with_wrappers(
../miniconda3/envs/keryu/lib/python3.12/site-packages/django/db/backends/utils.py:92: in _execute_with_wrappers
    return executor(sql, params, many, context)
../miniconda3/envs/keryu/lib/python3.12/site-packages/django/db/backends/utils.py:100: in _execute
    with self.db.wrap_database_errors:
../miniconda3/envs/keryu/lib/python3.12/site-packages/django/db/utils.py:91: in __exit__
    raise dj_exc_value.with_traceback(traceback) from exc_value
../miniconda3/envs/keryu/lib/python3.12/site-packages/django/db/backends/utils.py:105: in _execute
    return self.cursor.execute(sql, params)
_ _ _ _ _ _ _ _ _ _ _ _ _ _ _ _ _ _ _ _ _ _ _ _ _ _ _ _ _ _ _ _ _ _ _ _ _ _ _ _ 

self = <django.db.backends.sqlite3.base.SQLiteCursorWrapper object at 0x7c27b70b5130>
query = 'INSERT INTO "custodians_custodian" ("user_id", "phone_number", "emergency_phone", "address", "is_verified", "phone_ve..._attempts", "created_at", "updated_at") VALUES (?, ?, ?, ?, ?, ?, ?, ?, ?, ?, ?) RETURNING "custodians_custodian"."id"'
params = (12, '+1234567890', None, '', True, False, ...)

    def execute(self, query, params=None):
        if params is None:
            return super().execute(query)
        # Extract names if params is a mapping, i.e. "pyformat" style is used.
        param_names = list(params) if isinstance(params, Mapping) else None
        query = self.convert_query(query, param_names=param_names)
>       return super().execute(query, params)
E       django.db.utils.IntegrityError: UNIQUE constraint failed: custodians_custodian.user_id

../miniconda3/envs/keryu/lib/python3.12/site-packages/django/db/backends/sqlite3/base.py:329: IntegrityError
----------------------------- Captured stderr call -----------------------------
DEBUG 2025-04-09 06:41:52,307 models 5476 136510085551616 Created new custodian for user 11
DEBUG 2025-04-09 06:41:52,863 models 5476 136510085551616 Created new custodian for user 12
------------------------------ Captured log call -------------------------------
DEBUG    custodians.models:models.py:85 Created new custodian for user 11
DEBUG    custodians.models:models.py:85 Created new custodian for user 12
_______________ APIAuthenticationTests.test_unauthorized_access ________________

self = <django.db.backends.utils.CursorWrapper object at 0x7c27b72b9670>
sql = 'INSERT INTO "custodians_custodian" ("user_id", "phone_number", "emergency_phone", "address", "is_verified", "phone_ve... "created_at", "updated_at") VALUES (%s, %s, %s, %s, %s, %s, %s, %s, %s, %s, %s) RETURNING "custodians_custodian"."id"'
params = (12, '+1234567890', None, '', True, False, ...)
ignored_wrapper_args = (False, {'connection': <DatabaseWrapper vendor='sqlite' alias='default'>, 'cursor': <django.db.backends.utils.CursorWrapper object at 0x7c27b72b9670>})

    def _execute(self, sql, params, *ignored_wrapper_args):
        # Raise a warning during app initialization (stored_app_configs is only
        # ever set during testing).
        if not apps.ready and not apps.stored_app_configs:
            warnings.warn(self.APPS_NOT_READY_WARNING_MSG, category=RuntimeWarning)
        self.db.validate_no_broken_transaction()
        with self.db.wrap_database_errors:
            if params is None:
                # params default might be backend specific.
                return self.cursor.execute(sql)
            else:
>               return self.cursor.execute(sql, params)

../miniconda3/envs/keryu/lib/python3.12/site-packages/django/db/backends/utils.py:105: 
_ _ _ _ _ _ _ _ _ _ _ _ _ _ _ _ _ _ _ _ _ _ _ _ _ _ _ _ _ _ _ _ _ _ _ _ _ _ _ _ 

self = <django.db.backends.sqlite3.base.SQLiteCursorWrapper object at 0x7c27b70b43b0>
query = 'INSERT INTO "custodians_custodian" ("user_id", "phone_number", "emergency_phone", "address", "is_verified", "phone_ve..._attempts", "created_at", "updated_at") VALUES (?, ?, ?, ?, ?, ?, ?, ?, ?, ?, ?) RETURNING "custodians_custodian"."id"'
params = (12, '+1234567890', None, '', True, False, ...)

    def execute(self, query, params=None):
        if params is None:
            return super().execute(query)
        # Extract names if params is a mapping, i.e. "pyformat" style is used.
        param_names = list(params) if isinstance(params, Mapping) else None
        query = self.convert_query(query, param_names=param_names)
>       return super().execute(query, params)
E       sqlite3.IntegrityError: UNIQUE constraint failed: custodians_custodian.user_id

../miniconda3/envs/keryu/lib/python3.12/site-packages/django/db/backends/sqlite3/base.py:329: IntegrityError

The above exception was the direct cause of the following exception:

self = <test_authentication.APIAuthenticationTests testMethod=test_unauthorized_access>

    def setUp(self):
        # Create test users
        self.staff_user = User.objects.create_user(
            username='staff',
            password='staffpass123',
            email='staff@example.com',
            is_staff=True
        )
    
        self.custodian_user = User.objects.create_user(
            username='custodian',
            password='custodianpass123',
            email='custodian@example.com'
        )
    
>       self.custodian = Custodian.objects.create(
            user=self.custodian_user,
            phone_number='+1234567890',
            is_verified=True
        )

tests/auth/test_authentication.py:129: 
_ _ _ _ _ _ _ _ _ _ _ _ _ _ _ _ _ _ _ _ _ _ _ _ _ _ _ _ _ _ _ _ _ _ _ _ _ _ _ _ 
../miniconda3/envs/keryu/lib/python3.12/site-packages/django/db/models/manager.py:87: in manager_method
    return getattr(self.get_queryset(), name)(*args, **kwargs)
../miniconda3/envs/keryu/lib/python3.12/site-packages/django/db/models/query.py:679: in create
    obj.save(force_insert=True, using=self.db)
../miniconda3/envs/keryu/lib/python3.12/site-packages/django/db/models/base.py:822: in save
    self.save_base(
../miniconda3/envs/keryu/lib/python3.12/site-packages/django/db/models/base.py:909: in save_base
    updated = self._save_table(
../miniconda3/envs/keryu/lib/python3.12/site-packages/django/db/models/base.py:1067: in _save_table
    results = self._do_insert(
../miniconda3/envs/keryu/lib/python3.12/site-packages/django/db/models/base.py:1108: in _do_insert
    return manager._insert(
../miniconda3/envs/keryu/lib/python3.12/site-packages/django/db/models/manager.py:87: in manager_method
    return getattr(self.get_queryset(), name)(*args, **kwargs)
../miniconda3/envs/keryu/lib/python3.12/site-packages/django/db/models/query.py:1847: in _insert
    return query.get_compiler(using=using).execute_sql(returning_fields)
../miniconda3/envs/keryu/lib/python3.12/site-packages/django/db/models/sql/compiler.py:1823: in execute_sql
    cursor.execute(sql, params)
../miniconda3/envs/keryu/lib/python3.12/site-packages/django/db/backends/utils.py:79: in execute
    return self._execute_with_wrappers(
../miniconda3/envs/keryu/lib/python3.12/site-packages/django/db/backends/utils.py:92: in _execute_with_wrappers
    return executor(sql, params, many, context)
../miniconda3/envs/keryu/lib/python3.12/site-packages/django/db/backends/utils.py:100: in _execute
    with self.db.wrap_database_errors:
../miniconda3/envs/keryu/lib/python3.12/site-packages/django/db/utils.py:91: in __exit__
    raise dj_exc_value.with_traceback(traceback) from exc_value
../miniconda3/envs/keryu/lib/python3.12/site-packages/django/db/backends/utils.py:105: in _execute
    return self.cursor.execute(sql, params)
_ _ _ _ _ _ _ _ _ _ _ _ _ _ _ _ _ _ _ _ _ _ _ _ _ _ _ _ _ _ _ _ _ _ _ _ _ _ _ _ 

self = <django.db.backends.sqlite3.base.SQLiteCursorWrapper object at 0x7c27b70b43b0>
query = 'INSERT INTO "custodians_custodian" ("user_id", "phone_number", "emergency_phone", "address", "is_verified", "phone_ve..._attempts", "created_at", "updated_at") VALUES (?, ?, ?, ?, ?, ?, ?, ?, ?, ?, ?) RETURNING "custodians_custodian"."id"'
params = (12, '+1234567890', None, '', True, False, ...)

    def execute(self, query, params=None):
        if params is None:
            return super().execute(query)
        # Extract names if params is a mapping, i.e. "pyformat" style is used.
        param_names = list(params) if isinstance(params, Mapping) else None
        query = self.convert_query(query, param_names=param_names)
>       return super().execute(query, params)
E       django.db.utils.IntegrityError: UNIQUE constraint failed: custodians_custodian.user_id

../miniconda3/envs/keryu/lib/python3.12/site-packages/django/db/backends/sqlite3/base.py:329: IntegrityError
----------------------------- Captured stderr call -----------------------------
DEBUG 2025-04-09 06:41:53,604 models 5476 136510085551616 Created new custodian for user 11
DEBUG 2025-04-09 06:41:54,161 models 5476 136510085551616 Created new custodian for user 12
------------------------------ Captured log call -------------------------------
DEBUG    custodians.models:models.py:85 Created new custodian for user 11
DEBUG    custodians.models:models.py:85 Created new custodian for user 12
=============================== warnings summary ===============================
../miniconda3/envs/keryu/lib/python3.12/site-packages/drf_yasg/__init__.py:2
  /home/ubuntu/miniconda3/envs/keryu/lib/python3.12/site-packages/drf_yasg/__init__.py:2: DeprecationWarning: pkg_resources is deprecated as an API. See https://setuptools.pypa.io/en/latest/pkg_resources.html
    from pkg_resources import DistributionNotFound, get_distribution

-- Docs: https://docs.pytest.org/en/stable/how-to/capture-warnings.html
=========================== short test summary info ============================
FAILED tests/auth/test_authentication.py::AuthenticationTests::test_login_failure
FAILED tests/auth/test_authentication.py::AuthenticationTests::test_login_success
FAILED tests/auth/test_authentication.py::AuthenticationTests::test_logout - ...
FAILED tests/auth/test_authentication.py::AuthenticationTests::test_password_change
FAILED tests/auth/test_authentication.py::AuthenticationTests::test_password_reset
FAILED tests/auth/test_authentication.py::APIAuthenticationTests::test_permission_custodian_access
FAILED tests/auth/test_authentication.py::APIAuthenticationTests::test_permission_staff_access
FAILED tests/auth/test_authentication.py::APIAuthenticationTests::test_rate_limiting
FAILED tests/auth/test_authentication.py::APIAuthenticationTests::test_token_authentication
FAILED tests/auth/test_authentication.py::APIAuthenticationTests::test_token_expiration
FAILED tests/auth/test_authentication.py::APIAuthenticationTests::test_unauthorized_access
======================== 11 failed, 1 warning in 14.53s ========================

Exit code: 1
--------------------------------------------------------------------------------

Running tests in: tests/api/test_subjects_api.py
--------------------------------------------------------------------------------
============================= test session starts ==============================
platform linux -- Python 3.12.9, pytest-8.0.2, pluggy-1.5.0 -- /home/ubuntu/miniconda3/envs/keryu/bin/python
cachedir: .pytest_cache
django: version: 5.0.2
rootdir: /home/ubuntu/keryu3
plugins: django-4.8.0
collecting ... collected 12 items

tests/api/test_subjects_api.py::SubjectAPITests::test_create_subject_invalid FAILED [  8%]
tests/api/test_subjects_api.py::SubjectAPITests::test_create_subject_valid FAILED [ 16%]
tests/api/test_subjects_api.py::SubjectAPITests::test_delete_subject_custodian FAILED [ 25%]
